Workbook

Sheet 資產表
Q3: =R19 -> 現金比例 | R3: {=index(R20:R1012,Counta(R20:R1012))} -> 0.13325509
Q4: =W19 -> 基金比例 | R4: {=index(W20:W1012,Counta(W20:W1012))} -> 0.11281632
Q5: =AE19 -> 證券比例 | R5: {=index(AE20:AE1012,Counta(AE20:AE1012))} -> 0.64426912
Q6: TW Stock | R6: =R5-R7 -> 0.44669768
Q7: US Stock | R7: {=index(AF20:AF1012,Counta(AF20:AF1012))*R5} -> 0.19757144
Q8: TW Fund | R8: =R4-R9 -> 0.078191656
Q9: US Fund | R9: {=index(X20:X1012,Counta(X20:X1012))*R4} -> 0.034624662
Q10: Cash | R10: =R3 -> 0.13325509
Q11: Real Estate | R11: {=(index(AN42:AN1012,Counta(AN42:AN1012))-index(AV42:AV1012,Counta(AV42:AV1012)))/index(F42:F1012,Counta(F42:F1012))} -> 0.083637776
Q12: Crypto | R12: {=index(AJ20:AJ1012,Counta(AJ20:AJ1012))} -> 0.026021698
F14: 資產 | AV14: 負債
AR17: 即時匯率(USD) | AS17: =IFERROR(__xludf.DUMMYFUNCTION("GOOGLEFINANCE(""Currency:USDTWD"")"),31.426800000000004) -> 31.4268
C18: 收入 | E18: 月總收入(薪資+業外) | F18: 淨資產 (不含斜槓) | G18: 資產mom | H18: 資產yoy | I18: 銀行存款 | S18: 基金現值 | Y18: 證券現值 | AG18: 加密貨幣現值 | AK18: 斜槓資本 | AN18: 房屋累積投入資金 | AV18: 貸款餘額
A19: 統計日期 | B19: 月份 | C19: 薪資 | D19: 利息/回饋/投資 | I19: 國泰世華 | J19: 台新Richart | K19: 永豐DAWHO | L19: 郵局 | M19: 富邦網銀 | N19: 臺企銀 | O19: 國泰世華(美金) | P19: 富邦網銀(美金) | Q19: 總現金存款 | R19: 現金比例 | S19: 統一投信 | T19: 台新Richart | U19: 國泰投信(美金) | V19: 總基金現值 | W19: 基金比例 | X19: 美元基金比例 | Y19: 臺企銀證券 | Z19: 國泰證券 | AA19: 富邦證券(美金) | AB19: 國泰證券(美金) | AC19: 嘉信 (美金) | AD19: 總證券現值 | AE19: 證券比例 | AF19: 美股占證券比例 | AG19: 台灣交易所(MaicoinMax/ Hoyabit) | AH19: 海外交易所/錢包 | AI19: 總加密貨幣現值 | AJ19: 加密貨幣比例 | AK19: MoleculeX | AL19: Relifetek | AM19: 總斜槓資本額 | AO19: 睿來股權 | AP19: 聚動股權 | AQ19: 聚動股價 元/股 | AR19: 聚動股權現值 | AS19: 匯率 TWD/USD | AU19: Richart卡費 | AV19: 三信房貸
A20: 44766 | B20: 44766 | C20: 162321 | D20: 4319.21 | E20: =SUM(C20:D20) -> 166640.21 | F20: =SUM(Q20,V20,AD20,AN20)-AV20 -> 1592820.6 | G20: - | H20: - | I20: 317657 | J20: 5538 | K20: - | L20: 9023 | M20: 51239 | N20: 111823 | O20: 700.53 | P20: 125.58 | Q20: =SUM(I20:N20)+SUM(O20:P20)*$AS20 -> 519907.41 | R20: =Q20/F20 -> 0.32640677 | S20: 168939 | T20: 5658 | U20: 889.69 | V20: =SUM(S20:T20)+U20*$AS20 -> 201119.82 | W20: =V20/F20 -> 0.12626646 | X20: =sum(T20,U20*AS20)/V20 -> 0.16000818 | Y20: 651576 | Z20: 187740 | AA20: =272.7+816.73 -> 1089.43 | AC20: - | AD20: =SUM(Y20:Z20)+AA20*$AS20 -> 871793.32 | AE20: =AD20/F20 -> 0.54732677 | AF20: =SUM(AA20:AC20)*AS20/AD20 -> 0.037253468 | AG20: - | AH20: - | AJ20: - | AK20: 250000 | AL20: 250000 | AM20: =SUM(AK20:AL20) -> 500000 | AO20: 250000 | AP20: 250000 | AQ20: 1 | AR20: =AP20*AQ20 -> 250000 | AS20: 29.8113 | AU20: 17737
A21: 44807 | B21: 44804 | C21: 58076 | D21: 14540 | E21: =SUM(C21:D21) -> 72616 | F21: =SUM(Q21,V21,AD21,AN21)-AV21 -> 1597795.9 | G21: =(F21-F20)/F20 -> 0.0031235825 | H21: - | I21: 343132 | J21: 1715 | K21: - | L21: 2874 | M21: 21228 | N21: 20590 | O21: 600.53 | P21: 221.66 | Q21: =SUM(I21:N21)+SUM(O21:P21)*$AS21 -> 414719.97 | R21: =Q21/F21 -> 0.25955754 | S21: 180785 | T21: 6364 | U21: 923.66 | V21: =SUM(S21:T21)+U21*$AS21 -> 215437.66 | W21: =V21/F21 -> 0.13483428 | X21: =sum(T21,U21*AS21)/V21 -> 0.16084773 | Y21: 711110 | Z21: 200380 | AA21: =349.08+673.6+810.63 -> 1833.31 | AC21: - | AD21: =SUM(Y21:Z21)+AA21*$AS21 -> 967638.24 | AE21: =AD21/F21 -> 0.60560818 | AF21: =SUM(AA21:AC21)*AS21/AD21 -> 0.058026061 | AG21: - | AH21: - | AJ21: - | AK21: 250000 | AL21: 250000 | AM21: =SUM(AK21:AL21) -> 500000 | AO21: 250000 | AP21: 250000 | AQ21: 1 | AR21: =AP21*AQ21 -> 250000 | AS21: 30.6267 | AU21: 17245
A22: 44828 | B22: 44828 | C22: 69273 | D22: 21763 | E22: =SUM(C22:D22) -> 91036 | F22: =SUM(Q22,V22,AD22,AN22)-AV22 -> 1668736.6 | G22: =(F22-F21)/F21 -> 0.044399105 | H22: - | I22: =364133+25917 -> 390050 | J22: 3944 | K22: - | L22: 1720 | M22: 2221 | N22: 34212 | O22: 500.53 | P22: 821.66 | Q22: =SUM(I22:N22)+SUM(O22:P22)*$AS22 -> 474199.25 | R22: =Q22/F22 -> 0.28416663 | S22: 188988 | T22: 6844 | U22: 988.9 | V22: =SUM(S22:T22)+U22*$AS22 -> 227283.96 | W22: =V22/F22 -> 0.13620123 | X22: =sum(T22,U22*AS22)/V22 -> 0.16849391 | Y22: 701640 | Z22: 208656 | AA22: =328.04+636.8+825.99 -> 1790.83 | AC22: - | AD22: =SUM(Y22:Z22)+AA22*$AS22 -> 967253.35 | AE22: =AD22/F22 -> 0.57963214 | AF22: =SUM(AA22:AC22)*AS22/AD22 -> 0.058885656 | AG22: - | AH22: - | AJ22: - | AK22: 250000 | AL22: 250000 | AM22: =SUM(AK22:AL22) -> 500000 | AO22: 250000 | AP22: 250000 | AQ22: 1 | AR22: =AP22*AQ22 -> 250000 | AS22: 31.805 | AU22: 4957
A23: 44860 | B23: 44860 | C23: 51743 | D23: 22546.54 | E23: =SUM(C23:D23) -> 74289.54 | F23: =SUM(Q23,V23,AD23,AN23)-AV23 -> 1580257.9 | G23: =(F23-F22)/F22 -> -0.053021336 | H23: - | I23: =441659+50388 -> 492047 | J23: 4991 | K23: - | L23: 3695 | M23: 2221 | N23: =27860-13020 -> 14840 | O23: 400.53 | P23: 743.81 | Q23: =SUM(I23:N23)+SUM(O23:P23)*$AS23 -> 554834.57 | R23: =Q23/F23 -> 0.3511038 | S23: 167769 | T23: 7123 | U23: 1033.66 | V23: =SUM(S23:T23)+U23*$AS23 -> 208350.02 | W23: =V23/F23 -> 0.13184558 | X23: =sum(T23,U23*AS23)/V23 -> 0.19477331 | Y23: 678688 | Z23: 83545 | AA23: =419.7+640.8+633.75 -> 1694.25 | AC23: - | AD23: =SUM(Y23:Z23)+AA23*$AS23 -> 817073.33 | AE23: =AD23/F23 -> 0.51705061 | AF23: =SUM(AA23:AC23)*AS23/AD23 -> 0.067118004 | AG23: - | AH23: - | AJ23: - | AK23: 250000 | AL23: 250000 | AM23: =SUM(AK23:AL23) -> 500000 | AO23: 250000 | AP23: 250000 | AQ23: 1 | AR23: =AP23*AQ23 -> 250000 | AS23: 32.3685
A24: 44899 | B24: 44895 | C24: 51743 | D24: 13148 | E24: =SUM(C24:D24) -> 64891 | F24: =SUM(Q24,V24,AD24,AN24)-AV24 -> 1735312.1 | G24: =(F24-F23)/F23 -> 0.098119511 | H24: - | I24: =419950+47236 -> 467186 | J24: 1030 | K24: - | L24: 566 | M24: 2221 | N24: 1570 | O24: 1300.53 | P24: 752.97 | Q24: =SUM(I24:N24)+SUM(O24:P24)*$AS24 -> 535313.59 | R24: =Q24/F24 -> 0.30848261 | S24: 217486 | T24: 8168 | U24: 1178.47 | V24: =SUM(S24:T24)+U24*$AS24 -> 261659.79 | W24: =V24/F24 -> 0.15078544 | X24: =sum(T24,U24*AS24)/V24 -> 0.16882148 | Y24: 783954 | Z24: 102407 | AA24: =451.85+664.8+584.58 -> 1701.23 | AC24: - | AD24: =SUM(Y24:Z24)+AA24*$AS24 -> 938338.68 | AE24: =AD24/F24 -> 0.54073195 | AF24: =SUM(AA24:AC24)*AS24/AD24 -> 0.055393304 | AG24: - | AH24: - | AJ24: - | AK24: 250000 | AL24: 250000 | AM24: =SUM(AK24:AL24) -> 500000 | AO24: 250000 | AP24: 250000 | AQ24: 1 | AR24: =AP24*AQ24 -> 250000 | AS24: 30.553
A25: 44925 | B25: 44925 | C25: =51743+110190+7000 -> 168933 | D25: 5627.9 | E25: =SUM(C25:D25) -> 174560.9 | F25: =SUM(Q25,V25,AD25,AN25)-AV25 -> 1769795 | G25: =(F25-F24)/F24 -> 0.019871341 | H25: - | I25: =51964+453119 -> 505083 | J25: 1916 | K25: - | L25: 574 | M25: 2369 | N25: 2935 | O25: 1202.87 | P25: 627.38 | Q25: =SUM(I25:N25)+SUM(O25:P25)*$AS25 -> 569004.36 | R25: =Q25/F25 -> 0.32150862 | S25: 206934 | T25: 8016 | U25: 1112.3 | V25: =SUM(S25:T25)+U25*$AS25 -> 249060.35 | W25: =V25/F25 -> 0.14072836 | X25: =sum(T25,U25*AS25)/V25 -> 0.16914113 | Y25: 769186 | Z25: 135041 | AA25: =424.95+636.8+487.28 -> 1549.03 | AC25: - | AD25: =SUM(Y25:Z25)+AA25*$AS25 -> 951730.33 | AE25: =AD25/F25 -> 0.53776302 | AF25: =SUM(AA25:AC25)*AS25/AD25 -> 0.049912593 | AG25: - | AH25: - | AJ25: - | AK25: 350000 | AL25: 250000 | AM25: =SUM(AK25:AL25) -> 600000 | AO25: 250000 | AP25: 265625 | AQ25: 6.4 | AR25: =AP25*AQ25 -> 1700000 | AS25: 30.6665 | AU25: 聚動增資 +50000 (50000)
A26: 44956 | B26: 44956 | C26: 62193 | D26: 248.17 | E26: =SUM(C26:D26) -> 62441.17 | F26: =SUM(Q26,V26,AD26,AN26)-AV26 -> 1862470.9 | G26: =(F26-F25)/F25 -> 0.052365327 | H26: - | I26: =383774+41996 -> 425770 | J26: =11529-9276 -> 2253 | K26: - | L26: 695 | M26: 2369 | N26: 2935 | O26: 2102.87 | P26: =426.74+115.29 -> 542.03 | Q26: =SUM(I26:N26)+SUM(O26:P26)*$AS26 -> 513798.8 | R26: =Q26/F26 -> 0.27586943 | S26: 220040 | T26: 9115 | U26: 1353.41 | V26: =SUM(S26:T26)+U26*$AS26 -> 269977.23 | W26: =V26/F26 -> 0.14495648 | X26: =sum(T26,U26*AS26)/V26 -> 0.1849683 | Y26: 828283 | Z26: 192220 | AA26: =542.88+674.8+711.6 -> 1929.28 | AC26: - | AD26: =SUM(Y26:Z26)+AA26*$AS26 -> 1078694.9 | AE26: =AD26/F26 -> 0.57917409 | AF26: =SUM(AA26:AC26)*AS26/AD26 -> 0.053946586 | AG26: - | AH26: - | AJ26: - | AK26: 350000 | AL26: 250000 | AM26: =SUM(AK26:AL26) -> 600000 | AO26: 250000 | AP26: 265625 | AQ26: 6.4 | AR26: =AP26*AQ26 -> 1700000 | AS26: 30.1625
A27: 44985 | B27: 44985 | C27: 52394 | D27: =13230+251 -> 13481 | E27: =SUM(C27:D27) -> 65875 | F27: =SUM(Q27,V27,AD27,AN27)-AV27 -> 1918473.2 | G27: =(F27-F26)/F26 -> 0.030068778 | H27: - | I27: 420762 | J27: 795 | K27: - | L27: 569 | M27: 2369 | N27: 2935 | O27: 2002.87 | P27: 352.29 | Q27: =SUM(I27:N27)+SUM(O27:P27)*$AS27 -> 499647.45 | R27: =Q27/F27 -> 0.26044016 | S27: 249010 | T27: 9821 | U27: 1489.81 | V27: =SUM(S27:T27)+U27*$AS27 -> 304513.79 | W27: =V27/F27 -> 0.15872716 | X27: =sum(T27,U27*AS27)/V27 -> 0.1822702 | Y27: 831701 | Z27: 214323 | AA27: =532.86+656+1038.15 -> 2227.01 | AC27: - | AD27: =SUM(Y27:Z27)+AA27*$AS27 -> 1114311.9 | AE27: =AD27/F27 -> 0.58083269 | AF27: =SUM(AA27:AC27)*AS27/AD27 -> 0.06128259 | AG27: - | AH27: - | AJ27: - | AK27: 350000 | AL27: 250000 | AM27: =SUM(AK27:AL27) -> 600000 | AO27: 250000 | AP27: 265625 | AQ27: 6.4 | AR27: =AP27*AQ27 -> 1700000 | AS27: 30.6635
A28: 45014 | B28: 45014 | C28: 51697 | D28: 7886.32 | E28: =SUM(C28:D28) -> 59583.32 | F28: =SUM(Q28,V28,AD28,AN28)-AV28 -> 1958878.8 | G28: =(F28-F27)/F27 -> 0.02106133 | H28: - | I28: =16419+396558 -> 412977 | J28: 1266 | K28: - | L28: 1569 | M28: 2369 | N28: 2601 | O28: =257.6+1634.37 -> 1891.97 | P28: =131.33+95 -> 226.33 | Q28: =SUM(I28:N28)+SUM(O28:P28)*$AS28 -> 485330.41 | R28: =Q28/F28 -> 0.24775929 | S28: 262070 | T28: 10173 | U28: 1542.54 | V28: =SUM(S28:T28)+U28*$AS28 -> 319246.97 | W28: =V28/F28 -> 0.16297434 | X28: =sum(T28,U28*AS28)/V28 -> 0.17909949 | Y28: 853031 | Z28: 231461 | AA28: =101.03+676.4+1513.52 -> 2290.95 | AC28: - | AD28: =SUM(Y28:Z28)+AA28*$AS28 -> 1154301.4 | AE28: =AD28/F28 -> 0.58926637 | AF28: =SUM(AA28:AC28)*AS28/AD28 -> 0.060477595 | AG28: - | AH28: - | AJ28: - | AK28: 350000 | AL28: 250000 | AM28: =SUM(AK28:AL28) -> 600000 | AO28: 250000 | AP28: 265625 | AQ28: 6.4 | AR28: =AP28*AQ28 -> 1700000 | AS28: 30.4718
A29: 45045 | B29: 45045 | C29: 64241 | D29: 7371 | E29: =SUM(C29:D29) -> 71612 | F29: =SUM(Q29,V29,AD29,AN29)-AV29 -> 2011292.6 | G29: =(F29-F28)/F28 -> 0.026757082 | H29: - | I29: =480084+14278 -> 494362 | J29: 967 | K29: - | L29: 1690 | M29: 2017 | N29: 2601 | O29: 1535.33 | P29: 347.77 | Q29: =SUM(I29:N29)+SUM(O29:P29)*$AS29 -> 559556.26 | R29: =Q29/F29 -> 0.27820728 | S29: 269468 | T29: 10810 | U29: 1623.24 | V29: =SUM(S29:T29)+U29*$AS29 -> 330204.64 | W29: =V29/F29 -> 0.16417534 | X29: =sum(T29,U29*AS29)/V29 -> 0.18393637 | Y29: 872955 | Z29: 189684 | AA29: =107.34+1807.41 -> 1914.75 | AC29: - | AD29: =SUM(Y29:Z29)+AA29*$AS29 -> 1121531.7 | AE29: =AD29/F29 -> 0.55761738 | AF29: =SUM(AA29:AC29)*AS29/AD29 -> 0.052510981 | AG29: - | AH29: - | AJ29: - | AK29: 350000 | AL29: 250000 | AM29: =SUM(AK29:AL29) -> 600000 | AO29: 250000 | AP29: 265625 | AQ29: 6.4 | AR29: =AP29*AQ29 -> 1700000 | AS29: 30.7574
A30: 45075 | B30: 45075 | C30: 51660 | D30: 2273.77 | E30: =SUM(C30:D30) -> 53933.77 | F30: =SUM(Q30,V30,AD30,AN30)-AV30 -> 2148034.4 | G30: =(F30-F29)/F29 -> 0.067987015 | H30: - | I30: =428500+18342 -> 446842 | J30: 1817 | K30: - | L30: 1569 | M30: 2017 | N30: 2601 | O30: =435.33+242.7 -> 678.03 | P30: 194.46 | Q30: =SUM(I30:N30)+SUM(O30:P30)*$AS30 -> 481559.72 | R30: =Q30/F30 -> 0.22418622 | S30: 299504 | T30: 11844 | U30: 1823.4 | V30: =SUM(S30:T30)+U30*$AS30 -> 367176.5 | W30: =V30/F30 -> 0.17093604 | X30: =sum(T30,U30*AS30)/V30 -> 0.18430509 | Y30: 937532 | Z30: 197254 | AA30: 2442.56 | AC30: 2930.53 | AD30: =SUM(Y30:Z30)+(AA30+AC30)*$AS30 -> 1299298.2 | AE30: =AD30/F30 -> 0.60487774 | AF30: =SUM(AA30:AC30)*AS30/AD30 -> 0.1266162 | AG30: - | AH30: - | AJ30: - | AK30: 350000 | AL30: 250000 | AM30: =SUM(AK30:AL30) -> 600000 | AO30: 250000 | AP30: 265625 | AQ30: 6.4 | AR30: =AP30*AQ30 -> 1700000 | AS30: 30.6178
A31: 45102 | B31: 45102 | C31: =51961+80800 -> 132761 | D31: 4268 | E31: =SUM(C31:D31) -> 137029 | F31: =SUM(Q31,V31,AD31,AN31)-AV31 -> 2361353.4 | G31: =(F31-F30)/F30 -> 0.099308938 | H31: - | I31: =12323+517721 -> 530044 | J31: =30086-28281 -> 1805 | K31: - | L31: 6580 | M31: 2017 | N31: 2601 | O31: =343.73+252.03 -> 595.76 | P31: 196.39 | Q31: =SUM(I31:N31)+SUM(O31:P31)*$AS31 -> 567606.42 | R31: =Q31/F31 -> 0.24037334 | S31: 322948 | T31: 13404 | U31: 2150.75 | V31: =SUM(S31:T31)+U31*$AS31 -> 403032.78 | W31: =V31/F31 -> 0.17067872 | X31: =sum(T31,U31*AS31)/V31 -> 0.19870537 | Y31: 968828 | Z31: 229472 | AA31: =122.34+3079.2 -> 3201.54 | AC31: 3004.67 | AD31: =SUM(Y31:Z31)+(AA31+AC31)*$AS31 -> 1390714.2 | AE31: =AD31/F31 -> 0.58894794 | AF31: =SUM(AA31:AC31)*AS31/AD31 -> 0.13835641 | AG31: - | AH31: - | AJ31: - | AK31: 350000 | AL31: 250000 | AM31: =SUM(AK31:AL31) -> 600000 | AO31: 250000 | AP31: 265625 | AQ31: 6.4 | AR31: =AP31*AQ31 -> 1700000 | AS31: 31.0035
A32: 45137 | B32: 45137 | C32: =51660+21965 -> 73625 | D32: 33824 | E32: =SUM(C32:D32) -> 107449 | F32: =SUM(Q32,V32,AD32,AN32)-AV32 -> 2550295.3 | G32: =(F32-F31)/F31 -> 0.08001421 | H32: =(F32-F20)/F20 -> 0.60111901 | I32: =528648+27166 -> 555814 | J32: 2228 | K32: - | L32: 580 | M32: 2017 | N32: =131619-16297 -> 115322 | O32: 245.38 | P32: 196.39 | Q32: =SUM(I32:N32)+SUM(O32:P32)*$AS32 -> 689801.57 | R32: =Q32/F32 -> 0.2704791 | S32: 372217 | T32: 14442 | U32: 2378.23 | V32: =SUM(S32:T32)+U32*$AS32 -> 461168.47 | W32: =V32/F32 -> 0.18082944 | X32: =sum(T32,U32*AS32)/V32 -> 0.19288281 | Y32: 886087 | Z32: 315915 | AA32: 3329.86 | AC32: 2968.4 | AD32: =SUM(Y32:Z32)+(AA32+AC32)*$AS32 -> 1399325.2 | AE32: =AD32/F32 -> 0.54869146 | AF32: =SUM(AA32:AC32)*AS32/AD32 -> 0.14101313 | AG32: - | AH32: - | AJ32: - | AK32: 350000 | AL32: 250000 | AM32: =SUM(AK32:AL32) -> 600000 | AO32: 250000 | AP32: 265625 | AQ32: 6.4 | AR32: =AP32*AQ32 -> 1700000 | AS32: 31.3298
A33: 45173 | B33: 45169 | C33: 51660 | D33: 44007 | E33: =SUM(C33:D33) -> 95667 | F33: =SUM(Q33,V33,AD33,AN33)-AV33 -> 2453442.7 | G33: =(F33-F32)/F32 -> -0.037977008 | H33: =(F33-F21)/F21 -> 0.53551698 | I33: =563876+22769 -> 586645 | J33: 1831 | K33: - | L33: 14473 | M33: 10160 | N33: 62931 | O33: =145.38 -> 145.38 | P33: 812.86 | Q33: =SUM(I33:N33)+SUM(O33:P33)*$AS33 -> 706586.77 | R33: =Q33/F33 -> 0.28799808 | S33: 241758 | T33: 14468 | U33: 2324.02 | V33: =SUM(S33:T33)+U33*$AS33 -> 330311.11 | W33: =V33/F33 -> 0.13463168 | X33: =sum(T33,U33*AS33)/V33 -> 0.26809001 | Y33: 923479 | Z33: 297814 | AA33: =271.32+3185.13 -> 3456.45 | AC33: 2668.52 | AD33: =SUM(Y33:Z33)+(AA33+AC33)*$AS33 -> 1416544.8 | AE33: =AD33/F33 -> 0.57737024 | AF33: =SUM(AA33:AC33)*AS33/AD33 -> 0.13783665 | AG33: - | AH33: - | AJ33: - | AK33: 350000 | AL33: 250000 | AM33: =SUM(AK33:AL33) -> 600000 | AO33: 250000 | AP33: 265625 | AQ33: 6.4 | AR33: =AP33*AQ33 -> 1700000 | AS33: 31.878 | AU33: 基金贖回1/3
A34: 45205 | B34: 45199 | C34: 51811 | D34: 9771.96 | E34: =SUM(C34:D34) -> 61582.96 | F34: =SUM(Q34,V34,AD34,AN34)-AV34 -> 2453026.2 | G34: =(F34-F33)/F33 -> -0.00016974634 | H34: =(F34-F22)/F22 -> 0.46999009 | I34: =632667-51697+25084 -> 606054 | J34: 537 | K34: - | L34: 473 | M34: 10160 | N34: 12964 | O34: 46.79 | P34: 261.15 | Q34: =SUM(I34:N34)+SUM(O34:P34)*$AS34 -> 640106.29 | R34: =Q34/F34 -> 0.26094555 | S34: 255122 | T34: 13638 | U34: 2210.66 | V34: =SUM(S34:T34)+U34*$AS34 -> 339962.04 | W34: =V34/F34 -> 0.13858883 | X34: =sum(T34,U34*AS34)/V34 -> 0.2495574 | Y34: 965765 | Z34: 300767 | AA34: =286.4+270.14+3640.7 -> 4197.24 | AC34: 2211.81 | AD34: =SUM(Y34:Z34)+(AA34+AC34)*$AS34 -> 1472957.9 | AE34: =AD34/F34 -> 0.60046561 | AF34: =SUM(AA34:AC34)*AS34/AD34 -> 0.14014378 | AG34: - | AH34: - | AJ34: - | AK34: 350000 | AL34: 250000 | AM34: =SUM(AK34:AL34) -> 600000 | AO34: 250000 | AP34: 265625 | AQ34: 6.4 | AR34: =AP34*AQ34 -> 1700000 | AS34: 32.2085
A35: 45232 | B35: 45229 | C35: 51697 | D35: 580.84 | E35: =SUM(C35:D35) -> 52277.84 | F35: =SUM(Q35,V35,AD35,AN35)-AV35 -> 2379631.9 | G35: =(F35-F34)/F34 -> -0.029919923 | H35: =(F35-F23)/F23 -> 0.50585029 | I35: =17047+524667+9400 -> 551114 | J35: 1057 | K35: - | L35: 1583 | M35: 10160 | N35: 12964 | O35: =168.2+146.79 -> 314.99 | P35: 9.33 | Q35: =SUM(I35:N35)+SUM(O35:P35)*$AS35 -> 587368.29 | R35: =Q35/F35 -> 0.24683158 | S35: 246455 | T35: 13595 | U35: 2162.31 | V35: =SUM(S35:T35)+U35*$AS35 -> 329991 | W35: =V35/F35 -> 0.13867313 | X35: =sum(T35,U35*AS35)/V35 -> 0.25314629 | Y35: 962371 | Z35: 313291 | AA35: =330.02+379.35+2879.24 -> 3588.61 | AC35: 2180.68 | AD35: =SUM(Y35:Z35)+(AA35+AC35)*$AS35 -> 1462272.6 | AE35: =AD35/F35 -> 0.61449529 | AF35: =SUM(AA35:AC35)*AS35/AD35 -> 0.12761682 | AG35: - | AH35: - | AJ35: - | AK35: 350000 | AL35: 250000 | AM35: =SUM(AK35:AL35) -> 600000 | AO35: 250000 | AP35: 265625 | AQ35: 6.4 | AR35: =AP35*AQ35 -> 1700000 | AS35: 32.3455
A36: 45259 | B36: 45259 | C36: 56175 | D36: 360.05 | E36: =SUM(C36:D36) -> 56535.05 | F36: =SUM(Q36,V36,AD36,AN36)-AV36 -> 2515930.2 | G36: =(F36-F35)/F35 -> 0.057277071 | H36: =(F36-F24)/F24 -> 0.44984309 | I36: =23399+423205+81050 -> 527654 | J36: =2001+9665 -> 11666 | K36: - | L36: 583 | M36: 160 | N36: 31139 | O36: =192.5+46.79 -> 239.29 | P36: 336.6 | Q36: =SUM(I36:N36)+SUM(O36:P36)*$AS36 -> 589206.62 | R36: =Q36/F36 -> 0.23419037 | S36: 272069 | T36: 15413 | U36: 2575.82 | V36: =SUM(S36:T36)+U36*$AS36 -> 368012.44 | W36: =V36/F36 -> 0.14627291 | X36: =sum(T36,U36*AS36)/V36 -> 0.26070705 | Y36: 984411 | Z36: 366443 | AA36: =341.04+411.6+3454.08 -> 4206.72 | AC36: 2441.73 | AD36: =SUM(Y36:Z36)+(AA36+AC36)*$AS36 -> 1558711.1 | AE36: =AD36/F36 -> 0.61953672 | AF36: =SUM(AA36:AC36)*AS36/AD36 -> 0.13335193 | AG36: - | AH36: - | AJ36: - | AK36: 350000 | AL36: 250000 | AM36: =SUM(AK36:AL36) -> 600000 | AO36: 250000 | AP36: 265625 | AQ36: 13.5 | AR36: =AP36*AQ36 -> 3585937.5 | AS36: 31.264
A37: 45290 | B37: 45290 | C37: =51697+6000+117399 -> 175096 | D37: 12881 | E37: =SUM(C37:D37) -> 187977 | F37: =SUM(Q37,V37,AD37,AN37)-AV37 -> 2739417.8 | G37: =(F37-F36)/F36 -> 0.088828997 | H37: =(F37-F25)/F25 -> 0.54787289 | I37: =38995+514596+100000 -> 653591 | J37: =69+9945 -> 10014 | K37: - | L37: 2494 | M37: 173 | N37: 39918 | O37: 249.5 | P37: 218.04 | Q37: =SUM(I37:N37)+SUM(O37:P37)*$AS37 -> 720535.79 | R37: =Q37/F37 -> 0.26302516 | S37: 288346 | T37: =10629+6035 -> 16664 | U37: 3106.55 | V37: =SUM(S37:T37)+U37*$AS37 -> 400329.98 | W37: =V37/F37 -> 0.14613689 | X37: =sum(T37,U37*AS37)/V37 -> 0.27972919 | Y37: 1002842 | Z37: 394006 | AA37: =351.48+560.92+3544.52 -> 4456.92 | AC37: 2768.58 | AD37: =SUM(Y37:Z37)+(AA37+AC37)*$AS37 -> 1618552 | AE37: =AD37/F37 -> 0.59083796 | AF37: =SUM(AA37:AC37)*AS37/AD37 -> 0.13697675 | AG37: - | AH37: - | AJ37: - | AK37: 350000 | AL37: 250000 | AM37: =SUM(AK37:AL37) -> 600000 | AO37: 250000 | AP37: 265625 | AQ37: 13.5 | AR37: =AP37*AQ37 -> 3585937.5 | AS37: 30.68355
A38: 45323 | B38: 45322 | C38: 51197 | D38: 29050.42 | E38: =SUM(C38:D38) -> 80247.42 | F38: =SUM(Q38,V38,AD38,AN38)-AV38 -> 2698158.4 | G38: =(F38-F37)/F37 -> -0.015061375 | H38: =(F38-F26)/F26 -> 0.44869824 | I38: =465070+23362+10000 -> 498432 | J38: =4337+9582 -> 13919 | K38: 102985 | L38: 91210 | M38: 173 | N38: =67513-61048 -> 6465 | O38: =149.5+212 -> 361.5 | P38: 163.78 | Q38: =SUM(I38:N38)+SUM(O38:P38)*$AS38 -> 729633.3 | R38: =Q38/F38 -> 0.27041901 | S38: 214359 | T38: 11295 | U38: 3020.35 | V38: =SUM(S38:T38)+U38*$AS38 -> 320237.17 | W38: =V38/F38 -> 0.11868731 | X38: =sum(T38,U38*AS38)/V38 -> 0.33062423 | Y38: 1012863 | Z38: =292243+50150 -> 342393 | AA38: =312.2+560.4+2622.06 -> 3494.66 | AC38: 2669.48 | AD38: =SUM(Y38:Z38)+(AA38+AC38)*$AS38 -> 1548287.9 | AE38: =AD38/F38 -> 0.57383136 | AF38: =SUM(AA38:AC38)*AS38/AD38 -> 0.12467442 | AG38: - | AH38: - | AJ38: - | AK38: 350000 | AL38: 250000 | AM38: =SUM(AK38:AL38) -> 600000 | AN38: 100000 | AO38: 250000 | AP38: 265625 | AQ38: 13.5 | AR38: =AP38*AQ38 -> 3585937.5 | AS38: 31.3153
A39: 45350 | B39: 45350 | C39: =57667+3500 -> 61167 | D39: 4355 | E39: =SUM(C39:D39) -> 65522 | F39: =SUM(Q39,V39,AD39,AN39)-AV39 -> 2706574.4 | G39: =(F39-F38)/F38 -> 0.0031191694 | H39: =(F39-F27)/F27 -> 0.41079606 | I39: =299723+23362+57070 -> 380155 | J39: =9761+9582 -> 19343 | K39: 103089 | L39: 8513 | M39: 173 | N39: 6465 | O39: 49.5 | P39: 146.8 | Q39: =SUM(I39:N39)+SUM(O39:P39)*$AS39 -> 523952.37 | R39: =Q39/F39 -> 0.19358506 | S39: 231238 | T39: 12259 | U39: 3414.27 | V39: =SUM(S39:T39)+U39*$AS39 -> 351584.25 | W39: =V39/F39 -> 0.12990009 | X39: =sum(T39,U39*AS39)/V39 -> 0.34229705 | Y39: 1033765 | Z39: =300450+51250 -> 351700 | AA39: =353.21+555.52+2796.22 -> 3704.95 | AC39: 2472.82 | AD39: =SUM(Y39:Z39)+(AA39+AC39)*$AS39 -> 1581037.8 | AE39: =AD39/F39 -> 0.58414717 | AF39: =SUM(AA39:AC39)*AS39/AD39 -> 0.12369898 | AG39: - | AH39: - | AJ39: - | AK39: 350000 | AL39: 250000 | AM39: =SUM(AK39:AL39) -> 600000 | AN39: 250000 | AO39: 250000 | AP39: 265625 | AQ39: 13.5 | AR39: =AP39*AQ39 -> 3585937.5 | AS39: 31.6575
A40: 45382 | B40: 45382 | C40: 56697 | D40: 37439.45 | E40: =SUM(C40:D40) -> 94136.45 | F40: =SUM(Q40,V40,AD40,AN40)-AV40 -> 2706383.5 | G40: =(F40-F39)/F39 -> -7.0525291e-05 | H40: =(F40-F28)/F28 -> 0.38159827 | I40: =254522+120092+13821 -> 388435 | J40: =75+9669 -> 9744 | K40: 94386 | L40: 610 | M40: 173 | N40: =88284 -> 88284 | O40: =110.55+200.2 -> 310.75 | P40: 282.11 | Q40: =SUM(I40:N40)+SUM(O40:P40)*$AS40 -> 600568.48 | R40: =Q40/F40 -> 0.22190812 | S40: 249930 | T40: 13374 | U40: 3612.98 | V40: =SUM(S40:T40)+U40*$AS40 -> 378705.83 | W40: =V40/F40 -> 0.13993059 | X40: =sum(T40,U40*AS40)/V40 -> 0.34004185 | Y40: 1040965 | Z40: 251123 | AA40: =603.72+2636.85 -> 3240.57 | AC40: 2552.04 | AD40: =SUM(Y40:Z40)+(AA40+AC40)*$AS40 -> 1477109.2 | AE40: =AD40/F40 -> 0.54578709 | AF40: =SUM(AA40:AC40)*AS40/AD40 -> 0.12525897 | AG40: - | AH40: - | AJ40: - | AK40: 350000 | AL40: 250000 | AM40: =SUM(AK40:AL40) -> 600000 | AN40: 250000 | AO40: 250000 | AP40: 265625 | AQ40: 13.5 | AR40: =AP40*AQ40 -> 3585937.5 | AS40: 31.9409
A41: 45412 | B41: 45412 | C41: 58841 | D41: 5421.61 | E41: =SUM(C41:D41) -> 64262.61 | F41: =SUM(Q41,V41,AD41,AN41)-AV41 -> 2742000 | G41: =(F41-F40)/F40 -> 0.013160188 | H41: =(F41-F29)/F29 -> 0.36330237 | I41: =13821+348977 -> 362798 | J41: =2505+9425 -> 11930 | K41: 97624 | L41: 610 | M41: 173 | N41: =88284 -> 88284 | O41: =175.6+12.91 -> 188.51 | P41: 294.56 | Q41: =SUM(I41:N41)+SUM(O41:P41)*$AS41 -> 577177.23 | R41: =Q41/F41 -> 0.21049498 | S41: 257529 | T41: 11752 | U41: 3437.82 | V41: =SUM(S41:T41)+U41*$AS41 -> 381426.13 | W41: =V41/F41 -> 0.13910508 | X41: =sum(T41,U41*AS41)/V41 -> 0.32482601 | Y41: 1040819 | Z41: 308025 | AA41: =651.12+2749.2 -> 3400.32 | AC41: 2257.16 | AD41: =SUM(Y41:Z41)+(AA41+AC41)*$AS41 -> 1533396.7 | AE41: =AD41/F41 -> 0.55922562 | AF41: =SUM(AA41:AC41)*AS41/AD41 -> 0.12035546 | AG41: - | AH41: - | AJ41: - | AK41: 350000 | AL41: 250000 | AM41: =SUM(AK41:AL41) -> 600000 | AN41: 250000 | AO41: 250000 | AP41: 265625 | AQ41: 13.5 | AR41: =AP41*AQ41 -> 3585937.5 | AS41: 32.621 | AU41: 交屋 4/26貸款撥款 | AY41: =SUM(Q41,V41,AD41,11000000)/AV41 -> #DIV/0!
A42: 45448 | B42: 45443 | C42: =51697+1250 -> 52947 | D42: 357 | E42: =SUM(C42:D42) -> 53304 | F42: =SUM(Q42,V42,AD42,AN42)-AV42 -> 2838040.9 | G42: =(F42-F41)/F41 -> 0.035025854 | H42: =(F42-F30)/F30 -> 0.32122692 | I42: =13821+630138-51697 -> 592262 | J42: =417+9554 -> 9971 | K42: 112613 | L42: 610 | M42: 173 | N42: 57160 | O42: =195.2+212.91 -> 408.11 | P42: 294.56 | Q42: =SUM(I42:N42)+SUM(O42:P42)*$AS42 -> 795515.81 | R42: =Q42/F42 -> 0.28030456 | S42: 275832 | T42: 12574 | U42: 3374.18 | V42: =SUM(S42:T42)+U42*$AS42 -> 397538.79 | W42: =V42/F42 -> 0.14007507 | X42: =sum(T42,U42*AS42)/V42 -> 0.30615073 | Y42: 1101566 | Z42: 272928 | AA42: =692.68+2644.35 -> 3337.03 | AC42: 2447.14 | AD42: =SUM(Y42:Z42)+(AA42+AC42)*$AS42 -> 1561574.3 | AE42: =AD42/F42 -> 0.55022967 | AF42: =SUM(AA42:AC42)*AS42/AD42 -> 0.11980237 | AG42: - | AH42: - | AJ42: - | AK42: 350000 | AL42: 250000 | AM42: =SUM(AK42:AL42) -> 600000 | AN42: =11000000-2400000+250000 -> 8850000 | AO42: 250000 | AP42: 265625 | AQ42: 13.5 | AR42: =AP42*AQ42 -> 3585937.5 | AS42: 32.3435 | AU42: 裝潢 傢具支出 | AV42: =8800000-33412 -> 8766588 | AY42: =SUM(Q42,V42,AD42,11000000)/AV42 -> 1.5689832
A43: 45473 | B43: 45444 | C43: =51697+86272 -> 137969 | D43: =752+8867 -> 9619 | E43: =SUM(C43:D43) -> 147588 | F43: =SUM(Q43,V43,AD43,AN43)-AV43 -> 2762874.8 | G43: =(F43-F42)/F42 -> -0.026485214 | H43: =(F43-F31)/F31 -> 0.17003865 | I43: =13821+403716 -> 417537 | J43: =885+9223 -> 10108 | K43: 100429 | L43: 652 | M43: 173 | N43: =57160-29223 -> 27937 | O43: =188.3+114 -> 302.3 | P43: 296.48 | Q43: =SUM(I43:N43)+SUM(O43:P43)*$AS43 -> 576308.03 | R43: =Q43/F43 -> 0.20858999 | S43: 302295 | T43: 13274 | U43: 3646.45 | V43: =SUM(S43:T43)+U43*$AS43 -> 434149.73 | W43: =V43/F43 -> 0.15713696 | X43: =sum(T43,U43*AS43)/V43 -> 0.30370796 | Y43: 1178297 | Z43: 290945 | AA43: =741.96+2961.3 -> 3703.26 | AC43: 2396.65 | AD43: =SUM(Y43:Z43)+(AA43+AC43)*$AS43 -> 1667608 | AE43: =AD43/F43 -> 0.60357713 | AF43: =SUM(AA43:AC43)*AS43/AD43 -> 0.11895243 | AG43: - | AH43: - | AJ43: - | AK43: 350000 | AL43: 250000 | AM43: =SUM(AK43:AL43) -> 600000 | AN43: =11000000-2400000+250000 -> 8850000 | AO43: 250000 | AP43: 265625 | AQ43: 13.5 | AR43: =AP43*AQ43 -> 3585937.5 | AS43: 32.5195 | AU43: 裝潢 傢具 電器支出 | AV43: =8765191 -> 8765191 | AW43: =AV43-AV42 -> -1397
A44: 45505 | B44: 45474 | C44: =51697+63997 -> 115694 | D44: =13533.45+2289 -> 15822.45 | E44: =SUM(C44:D44) -> 131516.45 | F44: =SUM(Q44,V44,AD44,AN44)-AV44 -> 2878723.1 | G44: =(F44-F43)/F43 -> 0.041930366 | H44: =(F44-F32)/F32 -> 0.12878033 | I44: =13821+382108 -> 395929 | J44: =4140+9950 -> 14090 | K44: 113409 | L44: 1652 | M44: 173 | N44: 80573 | O44: =200.9+15.43 -> 216.33 | P44: 296.48 | Q44: =SUM(I44:N44)+SUM(O44:P44)*$AS44 -> 622621.55 | R44: =Q44/F44 -> 0.21628393 | S44: 290198 | T44: 9410 | U44: 3767.49 | V44: =SUM(S44:T44)+U44*$AS44 -> 423000.83 | W44: =V44/F44 -> 0.14694044 | X44: =sum(T44,U44*AS44)/V44 -> 0.31395407 | Y44: 1159731 | Z44: 349718 | AA44: =686.16+3481.05 -> 4167.21 | AC44: 2592.4 | AD44: =SUM(Y44:Z44)+(AA44+AC44)*$AS44 -> 1730839.7 | AE44: =AD44/F44 -> 0.60125259 | AF44: =SUM(AA44:AC44)*AS44/AD44 -> 0.12790944 | AG44: - | AH44: - | AJ44: - | AK44: 350000 | AL44: 250000 | AM44: =SUM(AK44:AL44) -> 600000 | AN44: =11000000-2400000+250000 -> 8850000 | AO44: 250000 | AP44: 265625 | AQ44: 13.5 | AR44: =AP44*AQ44 -> 3585937.5 | AS44: 32.752 | AV44: 8747739 | AW44: =AV44-AV43 -> -17452
A45: 45535 | B45: 45505 | C45: =56266 -> 56266 | D45: 14195.45 | E45: =SUM(C45:D45) -> 70461.45 | F45: =SUM(Q45,V45,AD45,AN45)-AV45 -> 2861217.5 | G45: =(F45-F44)/F44 -> -0.00608104 | H45: =(F45-F33)/F33 -> 0.16620516 | I45: =21478+308753 -> 330231 | J45: =2108+9996 -> 12104 | K45: 103187 | L45: 652 | M45: 173 | N45: 53706 | O45: 742.76 | P45: 97.88 | Q45: =SUM(I45:N45)+SUM(O45:P45)*$AS45 -> 526962.73 | R45: =Q45/F45 -> 0.1841743 | S45: 309001 | T45: 9905 | U45: 4090.51 | V45: =SUM(S45:T45)+U45*$AS45 -> 449847.32 | W45: =V45/F45 -> 0.15722234 | X45: =sum(T45,U45*AS45)/V45 -> 0.31309805 | Y45: 1152795 | Z45: 378772 | AA45: =647.12+3300.48 -> 3947.6 | AB45: 654.68 | AC45: 2679.45 | AD45: =SUM(Y45:Z45)+(AA45+AC45+AB45)*$AS45 -> 1764662.5 | AE45: =AD45/F45 -> 0.61675229 | AF45: =SUM(AA45:AC45)*AS45/AD45 -> 0.13209068 | AG45: - | AH45: - | AJ45: - | AK45: 350000 | AL45: 250000 | AM45: =SUM(AK45:AL45) -> 600000 | AN45: =11000000-2400000+250000 -> 8850000 | AO45: 250000 | AP45: 265625 | AQ45: 13.5 | AR45: =AP45*AQ45 -> 3585937.5 | AS45: 32.011 | AU45: 台幣升值美元資產減損，故較上月少~10000資產 | AV45: 8730255 | AW45: =AV45-AV44 -> -17484
...

Sheet Spot Holdings
B1: Holding Assets | E1: VIX INDEX | F1: =IFERROR(__xludf.DUMMYFUNCTION("GOOGLEFINANCE(""INDEXCBOE:VIX"",""price"")"),15.32) -> 15.32 | G1: SKEW INDEX | H1: =IFERROR(__xludf.DUMMYFUNCTION("GOOGLEFINANCE(""INDEXCBOE:SKEW"",""price"")"),144.18) -> 144.18
B2: Current Holdiing Value | E2: USD/TWD | F2: Total P/L Day | G2: Total P/L Day% | I2: Total Holding | L2: Cost Basis | M2: Total P/L | N2: Total P/L% | O2: 總報酬率(含息)
B3: =SUM(I6:I39) -> 3904601.2 | E3: =IFERROR(__xludf.DUMMYFUNCTION("GOOGLEFINANCE(""USDTWD"")"),31.426800000000004) -> 31.4268 | F3: =SUMPRODUCT(F6:F39,H6:H39) -> 39964.184 | G3: =F3/(I3-F3)*100% -> 0.010340993 | I3: =SUM(I6:I39) -> 3904601.2 | L3: =SUM(L6:L39) -> 2190622.7 | M3: =I3-L3 -> 1713978.5 | N3: =M3/L3 -> 0.78241612 | O3: =(M3+SUM(P3,Q3,R3,S3,T3))/L3 -> 0.90538284 | P3: =SUM(P6:P39) -> 13207 | Q3: =SUM(Q6:Q39) -> 35557.764 | R3: =SUM(R6:R39) -> 52674.896 | S3: =SUM(S6:S39) -> 79406.661 | T3: =SUM(T6:T39) -> 88527.36 | U3: =SUM(U6:U39) -> 27260 | V3: =SUM(P3:T3) -> 269373.68
B5: Symbol | C5: Exchange (Optional) | D5: Stock Name | E5: Current Price | F5: P/L Day | G5: P/L Day% | H5: Shares | I5: 預估現值 | J5: 持有現值比例 | K5: Trade Price | L5: 買進成本 | M5: P/L Open | N5: 含息報酬率 | O5: 產業類型 | P5: 2021年股息 | Q5: 2022年股息 | R5: 2023年股息 | S5: 2024年股息 | T5: 2025年股息 | U5: 2026年股息 | V5: 開始買進日 | W5: 持有天數
B6: TPE:00692 | D6: 00692 | E6: =IFERROR(__xludf.DUMMYFUNCTION("IF(ISBLANK(B6), 0, GOOGLEFINANCE(IF(ISBLANK(C6), B6, C6&"":""&B6), ""price""))"),90.45) -> 90.45 | F6: =IFERROR(__xludf.DUMMYFUNCTION("IF(ISBLANK(B6), 0, GOOGLEFINANCE(IF(ISBLANK(C6), B6, C6&"":""&B6), ""change""))"),3.2) -> 3.2 | G6: =IFERROR(__xludf.DUMMYFUNCTION("IF(ISBLANK(B6), 0, GOOGLEFINANCE(IF(ISBLANK(C6), B6, C6&"":""&B6), ""changepct"")/100)"),0.036699999999999997) -> 0.0367 | H6: ='00692 富邦公司治理'!J8 -> 7500 | I6: =H6 * E6 -> 678375 | J6: =I6/$I$3 -> 0.17373733 | K6: ='00692 富邦公司治理'!L8 -> 34.499067 | L6: =H6*K6 -> 258743 | M6: =I6-L6 -> 419632 | N6: =IF(H6=0,0,IF(L6=0,1,(M6+P6+Q6+R6+S6+T6+U6)/L6*100%)) -> 1.7539644 | O6: 指數型ETF | P6: 3914 | Q6: =2950+1375 -> 4325 | R6: =1820+4230 -> 6050 | S6: =1650+4190 -> 5840 | T6: =4700+9365 -> 14065 | V6: 43879 | W6: =DAYS(TODAY(),V6) -> 2293
B7: TPE:00878 | D7: 00878 | E7: =IFERROR(__xludf.DUMMYFUNCTION("IF(ISBLANK(B7), 0, GOOGLEFINANCE(IF(ISBLANK(C7), B7, C7&"":""&B7), ""price""))"),30.76) -> 30.76 | F7: =IFERROR(__xludf.DUMMYFUNCTION("IF(ISBLANK(B7), 0, GOOGLEFINANCE(IF(ISBLANK(C7), B7, C7&"":""&B7), ""change""))"),0.76) -> 0.76 | G7: =IFERROR(__xludf.DUMMYFUNCTION("IF(ISBLANK(B7), 0, GOOGLEFINANCE(IF(ISBLANK(C7), B7, C7&"":""&B7), ""changepct"")/100)"),0.0253) -> 0.0253 | H7: ='00878 國泰永續'!J8 -> 17243 | I7: =H7 * E7 -> 530394.68 | J7: =I7/$I$3 -> 0.13583837 | K7: ='00878 國泰永續'!L8 -> 18.604 | L7: =H7*K7 -> 320788.78 | M7: =I7-L7 -> 209605.9 | N7: =IF(H7=0,0,IF(L7=0,1,(M7+P7+Q7+R7+S7+T7+U7)/L7*100%)) -> 0.97423887 | O7: 高股息型ETF | P7: 1270 | Q7: =2470+2230+(11000*0.28-10)+3070 -> 10840 | R7: =(13000*0.27-10)+3500+4540+4540 -> 16080 | S7: =5330+6988+7815+8069 -> 28202 | T7: =7576+7374+6475+6617 -> 28042 | U7: =7126+11359 -> 18485 | V7: 44396 | W7: =DAYS(TODAY(),V7) -> 1776
B8: TPE:2330 | D8: 台積電 | E8: =IFERROR(__xludf.DUMMYFUNCTION("IF(ISBLANK(B8), 0, GOOGLEFINANCE(IF(ISBLANK(C8), B8, C8&"":""&B8), ""price""))"),2355.0) -> 2355 | F8: =IFERROR(__xludf.DUMMYFUNCTION("IF(ISBLANK(B8), 0, GOOGLEFINANCE(IF(ISBLANK(C8), B8, C8&"":""&B8), ""change""))"),60.0) -> 60 | G8: =IFERROR(__xludf.DUMMYFUNCTION("IF(ISBLANK(B8), 0, GOOGLEFINANCE(IF(ISBLANK(C8), B8, C8&"":""&B8), ""changepct"")/100)"),0.026099999999999998) -> 0.0261 | H8: ='2330 台積電'!J8 -> 160 | I8: =H8 * E8 -> 376800 | J8: =I8/$I$3 -> 0.096501532 | K8: ='2330 台積電'!L8 -> 1428.5062 | L8: =H8*K8 -> 228561 | M8: =I8-L8 -> 148239 | N8: =IF(H8=0,0,IF(L8=0,1,(M8+P8+Q8+R8+S8+T8+U8)/L8*100%)) -> 0.65946946 | O8: 電子/科技 | T8: =240+770+645 -> 1655 | U8: =835 -> 835 | V8: 45846 | W8: =DAYS(TODAY(),V8) -> 326
B9: TSLA | C9: NASDAQ | D9: TSLA | E9: =IFERROR(__xludf.DUMMYFUNCTION("IF(ISBLANK(B9), 0, GOOGLEFINANCE(IF(ISBLANK(C9), B9, C9&"":""&B9), ""price""))"),435.79) -> 435.79 | F9: =IFERROR(__xludf.DUMMYFUNCTION("IF(ISBLANK(B9), 0, GOOGLEFINANCE(IF(ISBLANK(C9), B9, C9&"":""&B9), ""change""))*$E$3"),-198.303108) -> -198.30311 | G9: =IFERROR(__xludf.DUMMYFUNCTION("IF(ISBLANK(B9), 0, GOOGLEFINANCE(IF(ISBLANK(C9), B9, C9&"":""&B9), ""changepct"")/100)"),-0.0143) -> -0.0143 | H9: 26 | I9: =H9 * E9*$E$3 -> 356082.61 | J9: =I9/$I$3 -> 0.091195642 | K9: =256.775 -> 256.775 | L9: =H9*K9*$E$3 -> 209810.03 | M9: =I9-L9 -> 146272.58 | N9: =IF(H9=0,0,IF(L9=0,1,(M9+P9+Q9+R9+S9+T9+U9)/L9*100%)) -> 0.69716678 | O9: 耐用消費品 | V9: 44755 | W9: =DAYS(TODAY(),V9) -> 1417
B10: RKLB | D10: RKLB | E10: =IFERROR(__xludf.DUMMYFUNCTION("IF(ISBLANK(B10), 0, GOOGLEFINANCE(IF(ISBLANK(C10), B10, C10&"":""&B10), ""price""))"),143.48) -> 143.48 | F10: =IFERROR(__xludf.DUMMYFUNCTION("IF(ISBLANK(B10), 0, GOOGLEFINANCE(IF(ISBLANK(C10), B10, C10&"":""&B10), ""change""))*$E$3"),-142.99194) -> -142.99194 | G10: =IFERROR(__xludf.DUMMYFUNCTION("IF(ISBLANK(B10), 0, GOOGLEFINANCE(IF(ISBLANK(C10), B10, C10&"":""&B10), ""changepct"")/100)"),-0.030699999999999998) -> -0.0307 | H10: 50 | I10: =H10 * E10*$E$3 -> 225455.86 | J10: =I10/$I$3 -> 0.057741073 | K10: 50.61 | L10: =H10*K10*$E$3 -> 79525.517 | M10: =I10-L10 -> 145930.35 | N10: =IF(H10=0,0,IF(L10=0,1,(M10+P10+Q10+R10+S10+T10+U10)/L10*100%)) -> 1.8350128 | O10: 電子/科技 | V10: 45834 | W10: =DAYS(TODAY(),V10) -> 338
B11: TPE:2890 | D11: 永豐金 | E11: =IFERROR(__xludf.DUMMYFUNCTION("IF(ISBLANK(B11), 0, GOOGLEFINANCE(IF(ISBLANK(C11), B11, C11&"":""&B11), ""price""))"),30.0) -> 30 | F11: =IFERROR(__xludf.DUMMYFUNCTION("IF(ISBLANK(B11), 0, GOOGLEFINANCE(IF(ISBLANK(C11), B11, C11&"":""&B11), ""change""))"),0.5) -> 0.5 | G11: =IFERROR(__xludf.DUMMYFUNCTION("IF(ISBLANK(B11), 0, GOOGLEFINANCE(IF(ISBLANK(C11), B11, C11&"":""&B11), ""changepct"")/100)"),0.0169) -> 0.0169 | H11: 7238 | I11: =H11 * E11 -> 217140 | J11: =I11/$I$3 -> 0.055611313 | K11: 21.88 | L11: =H11*K11 -> 158367.44 | M11: =I11-L11 -> 58772.56 | N11: =IF(H11=0,0,IF(L11=0,1,(M11+P11+Q11+R11+S11+T11+U11)/L11*100%)) -> 0.42505934 | O11: 金融 | Q11: 790 | R11: 590 | S11: 803 | T11: 6360 | V11: 44427 | W11: =DAYS(TODAY(),V11) -> 1745
B12: VTI | D12: VTI | E12: =IFERROR(__xludf.DUMMYFUNCTION("IF(ISBLANK(B12), 0, GOOGLEFINANCE(IF(ISBLANK(C12), B12, C12&"":""&B12), ""price""))"),372.54) -> 372.54 | F12: =IFERROR(__xludf.DUMMYFUNCTION("IF(ISBLANK(B12), 0, GOOGLEFINANCE(IF(ISBLANK(C12), B12, C12&"":""&B12), ""change""))*$E$3"),27.655584000000005) -> 27.655584 | G12: =IFERROR(__xludf.DUMMYFUNCTION("IF(ISBLANK(B12), 0, GOOGLEFINANCE(IF(ISBLANK(C12), B12, C12&"":""&B12), ""changepct"")/100)"),0.0024) -> 0.0024 | H12: =VTI!J8 -> 17.30997 | I12: =H12 * E12*$E$3 -> 202660.63 | J12: =I12/$I$3 -> 0.051903029 | K12: =VTI!L8 -> 307.66307 | L12: =H12*K12*$E$3 -> 167367.78 | M12: =I12-L12 -> 35292.852 | N12: =IF(H12=0,0,IF(L12=0,1,(M12+P12+Q12+R12+S12+T12+U12)/L12*100%)) -> 0.21089282 | O12: 指數型ETF | S12: 0.45 | T12: 3.36 | V12: 45162 | W12: =DAYS(TODAY(),V12) -> 1010
B13: TPE:2885 | D13: 元大金 | E13: =IFERROR(__xludf.DUMMYFUNCTION("IF(ISBLANK(B13), 0, GOOGLEFINANCE(IF(ISBLANK(C13), B13, C13&"":""&B13), ""price""))"),59.6) -> 59.6 | F13: =IFERROR(__xludf.DUMMYFUNCTION("IF(ISBLANK(B13), 0, GOOGLEFINANCE(IF(ISBLANK(C13), B13, C13&"":""&B13), ""change""))"),0.5) -> 0.5 | G13: =IFERROR(__xludf.DUMMYFUNCTION("IF(ISBLANK(B13), 0, GOOGLEFINANCE(IF(ISBLANK(C13), B13, C13&"":""&B13), ""changepct"")/100)"),0.0085) -> 0.0085 | H13: 3000 | I13: =H13 * E13 -> 178800 | J13: =I13/$I$3 -> 0.045792128 | K13: 22.02 | L13: =H13*K13 -> 66060 | M13: =I13-L13 -> 112740 | N13: =IF(H13=0,0,IF(L13=0,1,(M13+P13+Q13+R13+S13+T13+U13)/L13*100%)) -> 1.897366 | O13: 金融 | P13: 2390 | Q13: 2990 | R13: 1638 | S13: 2289 | T13: 3293 | V13: 44060 | W13: =DAYS(TODAY(),V13) -> 2112
B14: TPE:00881 | D14: 00881 | E14: =IFERROR(__xludf.DUMMYFUNCTION("IF(ISBLANK(B14), 0, GOOGLEFINANCE(IF(ISBLANK(C14), B14, C14&"":""&B14), ""price""))"),54.9) -> 54.9 | F14: =IFERROR(__xludf.DUMMYFUNCTION("IF(ISBLANK(B14), 0, GOOGLEFINANCE(IF(ISBLANK(C14), B14, C14&"":""&B14), ""change""))"),1.75) -> 1.75 | G14: =IFERROR(__xludf.DUMMYFUNCTION("IF(ISBLANK(B14), 0, GOOGLEFINANCE(IF(ISBLANK(C14), B14, C14&"":""&B14), ""changepct"")/100)"),0.0329) -> 0.0329 | H14: 3000 | I14: =H14 * E14 -> 164700 | J14: =I14/$I$3 -> 0.042181004 | K14: 17.29 | L14: =H14*K14 -> 51870 | M14: =I14-L14 -> 112830 | N14: =IF(H14=0,0,IF(L14=0,1,(M14+P14+Q14+R14+S14+T14+U14)/L14*100%)) -> 2.7989204 | O14: 科技主題型ETF | P14: 2150 | Q14: =2340+1030 -> 3370 | R14: =1390+2290 -> 3680 | S14: =3740+4990 -> 8730 | T14: =3740+2740 -> 6480 | U14: =7940 -> 7940 | V14: 44214 | W14: =DAYS(TODAY(),V14) -> 1958
B15: TPE:2480 | D15: 敦陽科 | E15: =IFERROR(__xludf.DUMMYFUNCTION("IF(ISBLANK(B15), 0, GOOGLEFINANCE(IF(ISBLANK(C15), B15, C15&"":""&B15), ""price""))"),148.5) -> 148.5 | F15: =IFERROR(__xludf.DUMMYFUNCTION("IF(ISBLANK(B15), 0, GOOGLEFINANCE(IF(ISBLANK(C15), B15, C15&"":""&B15), ""change""))"),1.5) -> 1.5 | G15: =IFERROR(__xludf.DUMMYFUNCTION("IF(ISBLANK(B15), 0, GOOGLEFINANCE(IF(ISBLANK(C15), B15, C15&"":""&B15), ""changepct"")/100)"),0.0102) -> 0.0102 | H15: 1000 | I15: =H15 * E15 -> 148500 | J15: =I15/$I$3 -> 0.038032053 | K15: 85.92 | L15: =H15*K15 -> 85920 | M15: =I15-L15 -> 62580 | N15: =IF(H15=0,0,IF(L15=0,1,(M15+P15+Q15+R15+S15+T15+U15)/L15*100%)) -> 0.96450186 | O15: 科技服務 | R15: 6250 | S15: 6630 | T15: 7410 | V15: 44778 | W15: =DAYS(TODAY(),V15) -> 1394
B16: TPE:2327 | D16: 國巨* | E16: =IFERROR(__xludf.DUMMYFUNCTION("IF(ISBLANK(B16), 0, GOOGLEFINANCE(IF(ISBLANK(C16), B16, C16&"":""&B16), ""price""))"),738.0) -> 738 | F16: =IFERROR(__xludf.DUMMYFUNCTION("IF(ISBLANK(B16), 0, GOOGLEFINANCE(IF(ISBLANK(C16), B16, C16&"":""&B16), ""change""))"),-4.0) -> -4 | G16: =IFERROR(__xludf.DUMMYFUNCTION("IF(ISBLANK(B16), 0, GOOGLEFINANCE(IF(ISBLANK(C16), B16, C16&"":""&B16), ""changepct"")/100)"),-0.0054) -> -0.0054 | H16: 200 | I16: =H16 * E16 -> 147600 | J16: =I16/$I$3 -> 0.037801555 | K16: 328.25 | L16: =H16*K16 -> 65650 | M16: =I16-L16 -> 81950 | N16: =IF(H16=0,0,IF(L16=0,1,(M16+P16+Q16+R16+S16+T16+U16)/L16*100%)) -> 1.2482864 | O16: 電子/科技 | V16: 46126 | W16: =DAYS(TODAY(),V16) -> 46
B17: GOOGL | D17: GOOGL | E17: =IFERROR(__xludf.DUMMYFUNCTION("IF(ISBLANK(B17), 0, GOOGLEFINANCE(IF(ISBLANK(C17), B17, C17&"":""&B17), ""price""))"),380.34) -> 380.34 | F17: =IFERROR(__xludf.DUMMYFUNCTION("IF(ISBLANK(B17), 0, GOOGLEFINANCE(IF(ISBLANK(C17), B17, C17&"":""&B17), ""change""))*$E$3"),-307.66837200000003) -> -307.66837 | G17: =IFERROR(__xludf.DUMMYFUNCTION("IF(ISBLANK(B17), 0, GOOGLEFINANCE(IF(ISBLANK(C17), B17, C17&"":""&B17), ""changepct"")/100)"),-0.025099999999999997) -> -0.0251 | H17: 12 | I17: =H17 * E17*$E$3 -> 143434.43 | J17: =I17/$I$3 -> 0.036734719 | K17: 155.06 | L17: =H17*K17*$E$3 -> 58476.475 | M17: =I17-L17 -> 84957.954 | N17: =IF(H17=0,0,IF(L17=0,1,(M17+P17+Q17+R17+S17+T17+U17)/L17*100%)) -> 1.452857 | O17: 科技服務 | V17: 45012 | W17: =DAYS(TODAY(),V17) -> 1160
B18: CURRENCY:BTC/USD | D18: $Bitcoin | E18: =IFERROR(__xludf.DUMMYFUNCTION("GOOGLEFINANCE(B18)"),73523.1) -> 73523.1 | H18: =0.01004+0.01221016+0.03118442 -> 0.05343458 | I18: =H18 * E18* $E$3 -> 123465.71 | J18: =I18/$I$3 -> 0.031620569 | K18: 94000 | L18: =H18*K18 *$E$3 -> 157852.12 | M18: =I18-L18 -> -34386.405 | N18: =IF(H18=0,0,IF(L18=0,1,(M18+P18+Q18+R18+S18+T18+U18)/L18*100%)) -> -0.21783936 | O18: Crypto | V18: 45864 | W18: =DAYS(TODAY(),V18) -> 308
B19: TPE:2887 | D19: 台新新光金 | E19: =IFERROR(__xludf.DUMMYFUNCTION("IF(ISBLANK(B19), 0, GOOGLEFINANCE(IF(ISBLANK(C19), B19, C19&"":""&B19), ""price""))"),23.35) -> 23.35 | F19: =IFERROR(__xludf.DUMMYFUNCTION("IF(ISBLANK(B19), 0, GOOGLEFINANCE(IF(ISBLANK(C19), B19, C19&"":""&B19), ""change""))"),0.35) -> 0.35 | G19: =IFERROR(__xludf.DUMMYFUNCTION("IF(ISBLANK(B19), 0, GOOGLEFINANCE(IF(ISBLANK(C19), B19, C19&"":""&B19), ""changepct"")/100)"),0.0152) -> 0.0152 | H19: ='2887 台新金'!J8 -> 5000 | I19: =H19 * E19 -> 116750 | J19: =I19/$I$3 -> 0.029900621 | K19: ='2887 台新金'!L8 -> 11.00958 | L19: =H19*K19 -> 55047.9 | M19: =I19-L19 -> 61702.1 | N19: =IF(H19=0,0,IF(L19=0,1,(M19+P19+Q19+R19+S19+T19+U19)/L19*100%)) -> 1.7692246 | O19: 金融 | P19: 1100 | Q19: 7260 | R19: 8150 | S19: 11990 | T19: 7190 | V19: 44403 | W19: =DAYS(TODAY(),V19) -> 1769
B20: NVDA | D20: =IFERROR(__xludf.DUMMYFUNCTION("IF(ISBLANK(B20), ""-"", GOOGLEFINANCE(IF(ISBLANK(C20), B20, C20&"":""&B20), ""name""))"),"NVIDIA Corp") -> NVIDIA Corp | E20: =IFERROR(__xludf.DUMMYFUNCTION("IF(ISBLANK(B20), 0, GOOGLEFINANCE(IF(ISBLANK(C20), B20, C20&"":""&B20), ""price""))"),211.14) -> 211.14 | F20: =IFERROR(__xludf.DUMMYFUNCTION("IF(ISBLANK(B20), 0, GOOGLEFINANCE(IF(ISBLANK(C20), B20, C20&"":""&B20), ""change""))*$E$3"),-97.73734800000001) -> -97.737348 | G20: =IFERROR(__xludf.DUMMYFUNCTION("IF(ISBLANK(B20), 0, GOOGLEFINANCE(IF(ISBLANK(C20), B20, C20&"":""&B20), ""changepct"")/100)"),-0.014499999999999999) -> -0.0145 | H20: 17 | I20: =H20 * E20*$E$3 -> 112802.73 | J20: =I20/$I$3 -> 0.028889692 | K20: 167.848 | L20: =H20*K20*$E$3 -> 89673.734 | M20: =I20-L20 -> 23128.993 | N20: =IF(H20=0,0,IF(L20=0,1,(M20+P20+Q20+R20+S20+T20+U20)/L20*100%)) -> 0.25792384 | O20: 電子/科技 | V20: 45817 | W20: =DAYS(TODAY(),V20) -> 355
B21: TPE:2834 | D21: 臺企銀 | E21: =IFERROR(__xludf.DUMMYFUNCTION("IF(ISBLANK(B21), 0, GOOGLEFINANCE(IF(ISBLANK(C21), B21, C21&"":""&B21), ""price""))"),16.25) -> 16.25 | F21: =IFERROR(__xludf.DUMMYFUNCTION("IF(ISBLANK(B21), 0, GOOGLEFINANCE(IF(ISBLANK(C21), B21, C21&"":""&B21), ""change""))"),0.35) -> 0.35 | G21: =IFERROR(__xludf.DUMMYFUNCTION("IF(ISBLANK(B21), 0, GOOGLEFINANCE(IF(ISBLANK(C21), B21, C21&"":""&B21), ""changepct"")/100)"),0.022000000000000002) -> 0.022 | H21: ='2834 臺企銀'!J8 -> 5019 | I21: =H21 * E21 -> 81558.75 | J21: =I21/$I$3 -> 0.020887856 | K21: ='2834 臺企銀'!L8 -> 8.1162283 | L21: =H21*K21 -> 40735.35 | M21: =I21-L21 -> 40823.4 | N21: =IF(H21=0,0,IF(L21=0,1,(M21+P21+Q21+R21+S21+T21+U21)/L21*100%)) -> 1.0733822 | O21: 金融 | P21: 310 | Q21: 390 | R21: 414.8 | S21: 849.4 | T21: 937 | V21: 43816 | W21: =DAYS(TODAY(),V21) -> 2356
B22: ASTS | D22: =IFERROR(__xludf.DUMMYFUNCTION("IF(ISBLANK(B22), ""-"", GOOGLEFINANCE(IF(ISBLANK(C22), B22, C22&"":""&B22), ""name""))"),"AST SpaceMobile Inc") -> AST SpaceMobile Inc | E22: =IFERROR(__xludf.DUMMYFUNCTION("IF(ISBLANK(B22), 0, GOOGLEFINANCE(IF(ISBLANK(C22), B22, C22&"":""&B22), ""price""))"),113.41) -> 113.41 | F22: =IFERROR(__xludf.DUMMYFUNCTION("IF(ISBLANK(B22), 0, GOOGLEFINANCE(IF(ISBLANK(C22), B22, C22&"":""&B22), ""change""))*$E$3"),-618.4794240000001) -> -618.47942 | G22: =IFERROR(__xludf.DUMMYFUNCTION("IF(ISBLANK(B22), 0, GOOGLEFINANCE(IF(ISBLANK(C22), B22, C22&"":""&B22), ""changepct"")/100)"),-0.1479) -> -0.1479 | H22: 10 | I22: =H22 * E22*$E$3 -> 35641.134 | J22: =I22/$I$3 -> 0.0091279831 | K22: =82.186 -> 82.186 | L22: =H22*K22*$E$3 -> 25828.43 | M22: =I22-L22 -> 9812.704 | N22: =IF(H22=0,0,IF(L22=0,1,(M22+P22+Q22+R22+S22)/L22*100%)) -> 0.37991872 | O22: 電子/科技 | V22: 46160 | W22: =DAYS(TODAY(),V22) -> 12
B23: UNCY | D23: UNCY | E23: =IFERROR(__xludf.DUMMYFUNCTION("IF(ISBLANK(B23), 0, GOOGLEFINANCE(IF(ISBLANK(C23), B23, C23&"":""&B23), ""price""))"),7.38) -> 7.38 | F23: =IFERROR(__xludf.DUMMYFUNCTION("IF(ISBLANK(B23), 0, GOOGLEFINANCE(IF(ISBLANK(C23), B23, C23&"":""&B23), ""change""))*$E$3"),11.313648) -> 11.313648 | G23: =IFERROR(__xludf.DUMMYFUNCTION("IF(ISBLANK(B23), 0, GOOGLEFINANCE(IF(ISBLANK(C23), B23, C23&"":""&B23), ""changepct"")/100)"),0.0513) -> 0.0513 | H23: 100 | I23: =H23 * E23* $E$3 -> 23192.978 | J23: =I23/$I$3 -> 0.0059399096 | K23: 6.8667 | L23: =H23*K23 *$E$3 -> 21579.841 | M23: =I23-L23 -> 1613.1376 | N23: =IF(H23=0,0,IF(L23=0,1,(M23+P23+Q23+R23+S23+T23+U23)/L23*100%)) -> 0.074752064 | O23: 健康科技 | V23: 45832 | W23: =DAYS(TODAY(),V23) -> 340
B24: CRCL | D24: =IFERROR(__xludf.DUMMYFUNCTION("IF(ISBLANK(B24), ""-"", GOOGLEFINANCE(IF(ISBLANK(C24), B24, C24&"":""&B24), ""name""))"),"Circle Internet Group Inc") -> Circle Internet Group Inc | E24: =IFERROR(__xludf.DUMMYFUNCTION("IF(ISBLANK(B24), 0, GOOGLEFINANCE(IF(ISBLANK(C24), B24, C24&"":""&B24), ""price""))"),113.0) -> 113 | F24: =IFERROR(__xludf.DUMMYFUNCTION("IF(ISBLANK(B24), 0, GOOGLEFINANCE(IF(ISBLANK(C24), B24, C24&"":""&B24), ""change""))*$E$3"),149.59156800000002) -> 149.59157 | G24: =IFERROR(__xludf.DUMMYFUNCTION("IF(ISBLANK(B24), 0, GOOGLEFINANCE(IF(ISBLANK(C24), B24, C24&"":""&B24), ""changepct"")/100)"),0.044000000000000004) -> 0.044 | H24: 6 | I24: =H24 * E24*$E$3 -> 21307.37 | J24: =I24/$I$3 -> 0.0054569901 | K24: 85.6 | L24: =H24*K24*$E$3 -> 16140.804 | M24: =I24-L24 -> 5166.5659 | N24: =IF(H24=0,0,IF(L24=0,1,(M24+P24+Q24+R24+S24+T24+U24)/L24*100%)) -> 0.32009346 | O24: 科技服務 | V24: 45973 | W24: =DAYS(TODAY(),V24) -> 199
B25: GRAB | D25: =IFERROR(__xludf.DUMMYFUNCTION("IF(ISBLANK(B25), ""-"", GOOGLEFINANCE(IF(ISBLANK(C25), B25, C25&"":""&B25), ""name""))"),"Grab Holdings Ltd") -> Grab Holdings Ltd | E25: =IFERROR(__xludf.DUMMYFUNCTION("IF(ISBLANK(B25), 0, GOOGLEFINANCE(IF(ISBLANK(C25), B25, C25&"":""&B25), ""price""))"),3.54) -> 3.54 | F25: =IFERROR(__xludf.DUMMYFUNCTION("IF(ISBLANK(B25), 0, GOOGLEFINANCE(IF(ISBLANK(C25), B25, C25&"":""&B25), ""change""))*$E$3"),0.0) -> 0 | G25: =IFERROR(__xludf.DUMMYFUNCTION("IF(ISBLANK(B25), 0, GOOGLEFINANCE(IF(ISBLANK(C25), B25, C25&"":""&B25), ""changepct"")/100)"),0.0) -> 0 | H25: 120 | I25: =H25 * E25*$E$3 -> 13350.105 | J25: =I25/$I$3 -> 0.0034190699 | K25: 4.8 | L25: =H25*K25*$E$3 -> 18101.837 | M25: =I25-L25 -> -4751.7322 | N25: =IF(H25=0,0,IF(L25=0,1,(M25+P25+Q25+R25+S25+T25+U25)/L25*100%)) -> -0.2625 | O25: 金融 | V25: 45659 | W25: =DAYS(TODAY(),V25) -> 513
B26: NVO | D26: =IFERROR(__xludf.DUMMYFUNCTION("IF(ISBLANK(B26), ""-"", GOOGLEFINANCE(IF(ISBLANK(C26), B26, C26&"":""&B26), ""name""))"),"Novo Nordisk A/S") -> Novo Nordisk A/S | E26: =IFERROR(__xludf.DUMMYFUNCTION("IF(ISBLANK(B26), 0, GOOGLEFINANCE(IF(ISBLANK(C26), B26, C26&"":""&B26), ""price""))"),45.58) -> 45.58 | F26: =IFERROR(__xludf.DUMMYFUNCTION("IF(ISBLANK(B26), 0, GOOGLEFINANCE(IF(ISBLANK(C26), B26, C26&"":""&B26), ""change""))*$E$3"),2.1998760000000006) -> 2.199876 | G26: =IFERROR(__xludf.DUMMYFUNCTION("IF(ISBLANK(B26), 0, GOOGLEFINANCE(IF(ISBLANK(C26), B26, C26&"":""&B26), ""changepct"")/100)"),0.0015) -> 0.0015 | H26: 4 | I26: =H26 * E26*$E$3 -> 5729.7342 | J26: =I26/$I$3 -> 0.0014674313 | K26: 106.65 | L26: =H26*K26*$E$3 -> 13406.673 | M26: =I26-L26 -> -7676.9387 | N26: =IF(H26=0,0,IF(L26=0,1,(M26+P26+Q26+R26+S26+T26+U26)/L26*100%)) -> -0.57262072 | O26: 健康科技 | V26: 45497 | W26: =DAYS(TODAY(),V26) -> 675
B27: AMZN | D27: =IFERROR(__xludf.DUMMYFUNCTION("IF(ISBLANK(B27), ""-"", GOOGLEFINANCE(IF(ISBLANK(C27), B27, C27&"":""&B27), ""name""))"),"Amazon.com Inc") -> Amazon.com Inc | E27: =IFERROR(__xludf.DUMMYFUNCTION("IF(ISBLANK(B27), 0, GOOGLEFINANCE(IF(ISBLANK(C27), B27, C27&"":""&B27), ""price""))"),270.64) -> 270.64 | F27: =IFERROR(__xludf.DUMMYFUNCTION("IF(ISBLANK(B27), 0, GOOGLEFINANCE(IF(ISBLANK(C27), B27, C27&"":""&B27), ""change""))*$E$3"),-105.59404800000002) -> -105.59405 | G27: =IFERROR(__xludf.DUMMYFUNCTION("IF(ISBLANK(B27), 0, GOOGLEFINANCE(IF(ISBLANK(C27), B27, C27&"":""&B27), ""changepct"")/100)"),-0.0123) -> -0.0123 | I27: =H27 * E27*$E$3 -> 0 | J27: =I27/$I$3 -> 0 | K27: 241.5675 | L27: =H27*K27*$E$3 -> 0 | M27: =I27-L27 -> 0 | N27: =IF(H27=0,0,IF(L27=0,1,(M27+P27+Q27+R27+S27)/L27*100%)) -> 0 | O27: 電子/科技 | V27: 46056 | W27: =DAYS(TODAY(),V27) -> 116
B28: TPE:2002 | D28: =IFERROR(__xludf.DUMMYFUNCTION("IF(ISBLANK(B28), ""-"", GOOGLEFINANCE(IF(ISBLANK(C28), B28, C28&"":""&B28), ""name""))"),"China Steel Corp") -> China Steel Corp | E28: =IFERROR(__xludf.DUMMYFUNCTION("IF(ISBLANK(B28), 0, GOOGLEFINANCE(IF(ISBLANK(C28), B28, C28&"":""&B28), ""price""))"),19.1) -> 19.1 | F28: =IFERROR(__xludf.DUMMYFUNCTION("IF(ISBLANK(B28), 0, GOOGLEFINANCE(IF(ISBLANK(C28), B28, C28&"":""&B28), ""change""))"),0.25) -> 0.25 | G28: =IFERROR(__xludf.DUMMYFUNCTION("IF(ISBLANK(B28), 0, GOOGLEFINANCE(IF(ISBLANK(C28), B28, C28&"":""&B28), ""changepct"")/100)"),0.013300000000000001) -> 0.0133 | H28: 45 | I28: =H28 * E28 -> 859.5 | J28: =I28/$I$3 -> 0.00022012491 | K28: 24.8 | L28: =H28*K28 -> 1116 | M28: =I28-L28 -> -256.5 | N28: =IF(H28=0,0,IF(L28=0,1,(M28+P28+Q28+R28+S28)/L28*100%)) -> -0.22983871 | O28: 工業 | V28: 43133 | W28: =DAYS(TODAY(),V28) -> 3039
B29: SCHD | D29: =IFERROR(__xludf.DUMMYFUNCTION("IF(ISBLANK(B29), ""-"", GOOGLEFINANCE(IF(ISBLANK(C29), B29, C29&"":""&B29), ""name""))"),"Schwab US Dividend Equity ETF") -> Schwab US Dividend Equity ETF | E29: =IFERROR(__xludf.DUMMYFUNCTION("IF(ISBLANK(B29), 0, GOOGLEFINANCE(IF(ISBLANK(C29), B29, C29&"":""&B29), ""price""))"),32.5) -> 32.5 | F29: =IFERROR(__xludf.DUMMYFUNCTION("IF(ISBLANK(B29), 0, GOOGLEFINANCE(IF(ISBLANK(C29), B29, C29&"":""&B29), ""change""))*$E$3"),-4.085484000000001) -> -4.085484 | G29: =IFERROR(__xludf.DUMMYFUNCTION("IF(ISBLANK(B29), 0, GOOGLEFINANCE(IF(ISBLANK(C29), B29, C29&"":""&B29), ""changepct"")/100)"),-0.004) -> -0.004 | H29: =21.6612-21.6612 -> 0 | I29: =H29 * E29*$E$3 -> 0 | J29: =I29/$I$3 -> 0 | K29: =24.33 -> 24.33 | L29: =H29*K29*$E$3 -> 0 | M29: =I29-L29 -> 0 | N29: =IF(H29=0,0,IF(L29=0,1,(M29+P29+Q29+R29+S29)/L29*100%)) -> 0 | O29: 高股息型ETF | V29: 45068 | W29: =DAYS(TODAY(),V29) -> 1104
B30: TPE:00713 | D30: 00713 | E30: =IFERROR(__xludf.DUMMYFUNCTION("IF(ISBLANK(B30), 0, GOOGLEFINANCE(IF(ISBLANK(C30), B30, C30&"":""&B30), ""price""))"),56.55) -> 56.55 | F30: =IFERROR(__xludf.DUMMYFUNCTION("IF(ISBLANK(B30), 0, GOOGLEFINANCE(IF(ISBLANK(C30), B30, C30&"":""&B30), ""change""))"),0.8) -> 0.8 | G30: =IFERROR(__xludf.DUMMYFUNCTION("IF(ISBLANK(B30), 0, GOOGLEFINANCE(IF(ISBLANK(C30), B30, C30&"":""&B30), ""changepct"")/100)"),0.0143) -> 0.0143 | I30: =H30 * E30 -> 0 | J30: =I30/$I$3 -> 0 | K30: 53.4 | L30: =H30*K30 -> 0 | M30: =I30-L30 -> 0 | N30: =IF(H30=0,0,IF(L30=0,1,(M30+P30+Q30+R30+S30+T30)/L30*100%)) -> 0 | O30: 高股息型ETF | R30: 746 | S30: =1092+2495+3270+3563 -> 10420 | T30: =3976+3907+2900 -> 10783 | V30: 45261 | W30: =DAYS(TODAY(),V30) -> 911
B31: PL | D31: =IFERROR(__xludf.DUMMYFUNCTION("IF(ISBLANK(B31), ""-"", GOOGLEFINANCE(IF(ISBLANK(C31), B31, C31&"":""&B31), ""name""))"),"Planet Labs PBC") -> Planet Labs PBC | E31: =IFERROR(__xludf.DUMMYFUNCTION("IF(ISBLANK(B31), 0, GOOGLEFINANCE(IF(ISBLANK(C31), B31, C31&"":""&B31), ""price""))"),51.14) -> 51.14 | F31: =IFERROR(__xludf.DUMMYFUNCTION("IF(ISBLANK(B31), 0, GOOGLEFINANCE(IF(ISBLANK(C31), B31, C31&"":""&B31), ""change""))*$E$3"),-8.170968000000002) -> -8.170968 | G31: =IFERROR(__xludf.DUMMYFUNCTION("IF(ISBLANK(B31), 0, GOOGLEFINANCE(IF(ISBLANK(C31), B31, C31&"":""&B31), ""changepct"")/100)"),-0.0051) -> -0.0051 | I31: =H31 * E31*$E$3 -> 0 | J31: =I31/$I$3 -> 0 | K31: 8.1165 | L31: =H31*K31 *$E$3 -> 0 | M31: =I31-L31 -> 0 | N31: =IF(H31=0,0,IF(L31=0,1,(M31+P31+Q31+R31+S31)/L31*100%)) -> 0 | O31: 電子/科技 | W31: =DAYS(TODAY(),V31) -> 46172
B32: TPE:2317 | D32: 鴻海 | E32: =IFERROR(__xludf.DUMMYFUNCTION("IF(ISBLANK(B32), 0, GOOGLEFINANCE(IF(ISBLANK(C32), B32, C32&"":""&B32), ""price""))"),289.0) -> 289 | F32: =IFERROR(__xludf.DUMMYFUNCTION("IF(ISBLANK(B32), 0, GOOGLEFINANCE(IF(ISBLANK(C32), B32, C32&"":""&B32), ""change""))"),26.0) -> 26 | G32: =IFERROR(__xludf.DUMMYFUNCTION("IF(ISBLANK(B32), 0, GOOGLEFINANCE(IF(ISBLANK(C32), B32, C32&"":""&B32), ""changepct"")/100)"),0.0989) -> 0.0989 | I32: =H32 * E32 -> 0 | J32: =I32/$I$3 -> 0 | K32: 207 | L32: =H32*K32 -> 0 | M32: =I32-L32 -> 0 | N32: =IF(H32=0,0,IF(L32=0,1,(M32+P32+Q32+R32+T32)/L32*100%)) -> 0 | O32: 電子/科技 | T32: 2309 | V32: 45597 | W32: =DAYS(TODAY(),V32) -> 575
B33: TPE:2301 | D33: =IFERROR(__xludf.DUMMYFUNCTION("IF(ISBLANK(B33), ""-"", GOOGLEFINANCE(IF(ISBLANK(C33), B33, C33&"":""&B33), ""name""))"),"Lite-On Technology Corp") -> Lite-On Technology Corp | E33: =IFERROR(__xludf.DUMMYFUNCTION("IF(ISBLANK(B33), 0, GOOGLEFINANCE(IF(ISBLANK(C33), B33, C33&"":""&B33), ""price""))"),234.5) -> 234.5 | F33: =IFERROR(__xludf.DUMMYFUNCTION("IF(ISBLANK(B33), 0, GOOGLEFINANCE(IF(ISBLANK(C33), B33, C33&"":""&B33), ""change""))"),4.0) -> 4 | G33: =IFERROR(__xludf.DUMMYFUNCTION("IF(ISBLANK(B33), 0, GOOGLEFINANCE(IF(ISBLANK(C33), B33, C33&"":""&B33), ""changepct"")/100)"),0.0174) -> 0.0174 | I33: =H33 * E33 -> 0 | J33: =I33/$I$3 -> 0 | K33: =((((65.47*1012)+9413)/1112)*900+13900+14405+8643)/1200 -> 81.825504 | L33: =H33*K33 -> 0 | M33: =I33-L33 -> 0 | N33: =IF(H33=0,0,IF(L33=0,1,(M33+P33+Q33+R33+S33)/L33*100%)) -> 0 | O33: 電子/科技 | P33: 1990 | Q33: =1630+453 -> 2083 | R33: =2426+1990 -> 4416 | S33: =3002 -> 3002 | V33: 44432 | W33: 947天 2024/03/29平倉
B34: TSLY | D34: =IFERROR(__xludf.DUMMYFUNCTION("IF(ISBLANK(B34), ""-"", GOOGLEFINANCE(IF(ISBLANK(C34), B34, C34&"":""&B34), ""name""))"),"YieldMax TSLA Option Income Strategy ETF") -> YieldMax TSLA Option Income Strategy ETF | E34: =IFERROR(__xludf.DUMMYFUNCTION("IF(ISBLANK(B34), 0, GOOGLEFINANCE(IF(ISBLANK(C34), B34, C34&"":""&B34), ""price""))"),30.63) -> 30.63 | F34: =IFERROR(__xludf.DUMMYFUNCTION("IF(ISBLANK(B34), 0, GOOGLEFINANCE(IF(ISBLANK(C34), B34, C34&"":""&B34), ""change""))*$E$3"),-8.170968000000002) -> -8.170968 | G34: =IFERROR(__xludf.DUMMYFUNCTION("IF(ISBLANK(B34), 0, GOOGLEFINANCE(IF(ISBLANK(C34), B34, C34&"":""&B34), ""changepct"")/100)"),-0.0084) -> -0.0084 | I34: =H34 * E34*$E$3 -> 0 | J34: =I34/$I$3 -> 0 | K34: 26.6 | L34: =H34*K34 *$E$3 -> 0 | M34: =I34-L34 -> 0 | N34: =IF(H34=0,0,IF(L34=0,1,(M34+P34+Q34+R34+S34)/L34*100%)) -> 0 | O34: 高股息ETF | R34: =(8.19+8.0766+11.8755+12.2612+11.3071)*$E$3 -> 1625.0924 | S34: =(9.9225+10.7863)*$E$3 -> 650.81132 | V34: 45056 | W34: =DAYS(TODAY(),V34) -> 1116
B35: TPE:2891 | D35: =IFERROR(__xludf.DUMMYFUNCTION("IF(ISBLANK(B35), ""-"", GOOGLEFINANCE(IF(ISBLANK(C35), B35, C35&"":""&B35), ""name""))"),"CTBC Financial Holding Co Ltd") -> CTBC Financial Holding Co Ltd | E35: =IFERROR(__xludf.DUMMYFUNCTION("IF(ISBLANK(B35), 0, GOOGLEFINANCE(IF(ISBLANK(C35), B35, C35&"":""&B35), ""price""))"),60.5) -> 60.5 | F35: =IFERROR(__xludf.DUMMYFUNCTION("IF(ISBLANK(B35), 0, GOOGLEFINANCE(IF(ISBLANK(C35), B35, C35&"":""&B35), ""change""))"),1.2) -> 1.2 | G35: =IFERROR(__xludf.DUMMYFUNCTION("IF(ISBLANK(B35), 0, GOOGLEFINANCE(IF(ISBLANK(C35), B35, C35&"":""&B35), ""changepct"")/100)"),0.0202) -> 0.0202 | I35: =H35 * E35 -> 0 | J35: =I35/$I$3 -> 0 | K35: 24.87 | L35: =H35*K35 -> 0 | M35: =I35-L35 -> 0 | N35: =IF(H35=0,0,IF(L35=0,0,(M35+P35+Q35)/L35*100%)) -> 0 | O35: 金控 | V35: 45148 | W35: =DAYS(TODAY(),V35) -> 1024
B36: TPE:6257 | D36: =IFERROR(__xludf.DUMMYFUNCTION("IF(ISBLANK(B36), ""-"", GOOGLEFINANCE(IF(ISBLANK(C36), B36, C36&"":""&B36), ""name""))"),"Sigurd Microelectronics Corp") -> Sigurd Microelectronics Corp | E36: =IFERROR(__xludf.DUMMYFUNCTION("IF(ISBLANK(B36), 0, GOOGLEFINANCE(IF(ISBLANK(C36), B36, C36&"":""&B36), ""price""))"),227.5) -> 227.5 | F36: =IFERROR(__xludf.DUMMYFUNCTION("IF(ISBLANK(B36), 0, GOOGLEFINANCE(IF(ISBLANK(C36), B36, C36&"":""&B36), ""change""))"),-1.5) -> -1.5 | G36: =IFERROR(__xludf.DUMMYFUNCTION("IF(ISBLANK(B36), 0, GOOGLEFINANCE(IF(ISBLANK(C36), B36, C36&"":""&B36), ""changepct"")/100)"),-0.0066) -> -0.0066 | I36: =H36 * E36 -> 0 | J36: =I36/$I$3 -> 0 | K36: 49.519 | L36: =H36*K36 -> 0 | M36: =I36-L36 -> 0 | N36: =IF(H36=0,0,IF(L36=0,1,(M36+P36+Q36+R36)/L36*100%)) -> 0 | O36: 電子/科技 | V36: 44936 | W36: =DAYS(TODAY(),V36) -> 1236
B37: QYLD | D37: =IFERROR(__xludf.DUMMYFUNCTION("IF(ISBLANK(B37), ""-"", GOOGLEFINANCE(IF(ISBLANK(C37), B37, C37&"":""&B37), ""name""))"),"Global X NASDAQ 100 Covered Call ETF") -> Global X NASDAQ 100 Covered Call ETF | E37: =IFERROR(__xludf.DUMMYFUNCTION("IF(ISBLANK(B37), 0, GOOGLEFINANCE(IF(ISBLANK(C37), B37, C37&"":""&B37), ""price""))"),18.08) -> 18.08 | F37: =IFERROR(__xludf.DUMMYFUNCTION("IF(ISBLANK(B37), 0, GOOGLEFINANCE(IF(ISBLANK(C37), B37, C37&"":""&B37), ""change""))*$E$3"),0.9428040000000001) -> 0.942804 | G37: =IFERROR(__xludf.DUMMYFUNCTION("IF(ISBLANK(B37), 0, GOOGLEFINANCE(IF(ISBLANK(C37), B37, C37&"":""&B37), ""changepct"")/100)"),0.0017000000000000001) -> 0.0017 | H37: =QYLD!J8 -> 0 | I37: =H37 * E37*$E$3 -> 0 | J37: =I37/$I$3 -> 0 | K37: =QYLD!L8 -> 17.68 | L37: =H37*K37*$E$3 -> 0 | M37: =I37-L37 -> 0 | N37: =IF(H37=0,0,IF(L37=0,1,(M37+P37+Q37+R37)/L37*100%)) -> 0 | O37: 高股息ETF | Q37: =(19.45)*$E$3 -> 611.25126 | R37: =(4.75+4.68+4.73)*$E$3 -> 445.00349 | V37: 44729 | W37: =DAYS(TODAY(),V37) -> 1443
B38: ITOT | D38: =IFERROR(__xludf.DUMMYFUNCTION("IF(ISBLANK(B38), ""-"", GOOGLEFINANCE(IF(ISBLANK(C38), B38, C38&"":""&B38), ""name""))"),"iShares Core S&P Total US Stock Market ETF") -> iShares Core S&P Total US Stock Market ETF | E38: =IFERROR(__xludf.DUMMYFUNCTION("IF(ISBLANK(B38), 0, GOOGLEFINANCE(IF(ISBLANK(C38), B38, C38&"":""&B38), ""price""))"),165.48) -> 165.48 | F38: =IFERROR(__xludf.DUMMYFUNCTION("IF(ISBLANK(B38), 0, GOOGLEFINANCE(IF(ISBLANK(C38), B38, C38&"":""&B38), ""change""))*$E$3"),13.827792000000002) -> 13.827792 | G38: =IFERROR(__xludf.DUMMYFUNCTION("IF(ISBLANK(B38), 0, GOOGLEFINANCE(IF(ISBLANK(C38), B38, C38&"":""&B38), ""changepct"")/100)"),0.0027) -> 0.0027 | I38: =H38 * E38*$E$3 -> 0 | J38: =I38/$I$3 -> 0 | K38: =ITOT!L8 -> 90.998333 | L38: =H38*K38*$E$3 -> 0 | M38: =I38-L38 -> 0 | N38: =IF(H38=0,0,IF(L38=0,1,(M38+P38+Q38+R38)/L38*100%)) -> 0 | O38: =ITOT!N8 -> 指數ETF | Q38: =(1.13)*$E$3 -> 35.512284 | V38: 44781 | W38: =DAYS(TODAY(),V38) -> 1391
B39: TPE:0050 | D39: =IFERROR(__xludf.DUMMYFUNCTION("IF(ISBLANK(B39), ""-"", GOOGLEFINANCE(IF(ISBLANK(C39), B39, C39&"":""&B39), ""name""))"),"Yuanta/P-shares Taiwan Top 50 ETF") -> Yuanta/P-shares Taiwan Top 50 ETF | E39: =IFERROR(__xludf.DUMMYFUNCTION("IF(ISBLANK(B39), 0, GOOGLEFINANCE(IF(ISBLANK(C39), B39, C39&"":""&B39), ""price""))"),105.4) -> 105.4 | F39: =IFERROR(__xludf.DUMMYFUNCTION("IF(ISBLANK(B39), 0, GOOGLEFINANCE(IF(ISBLANK(C39), B39, C39&"":""&B39), ""change""))"),4.9) -> 4.9 | G39: =IFERROR(__xludf.DUMMYFUNCTION("IF(ISBLANK(B39), 0, GOOGLEFINANCE(IF(ISBLANK(C39), B39, C39&"":""&B39), ""changepct"")/100)"),0.048799999999999996) -> 0.0488 | H39: ='0050 元大台50'!J8 -> 0 | I39: =H39 * E39 -> 0 | J39: =I39/$I$3 -> 0 | K39: ='0050 元大台50'!L8 -> 128.01475 | L39: =H39*K39 -> 0 | M39: =I39-L39 -> 0 | N39: =IF(H39=0,0,IF(L39=0,1,(M39+P39+Q39+R39)/L39*100%)) -> 0 | O39: 指數ETF | P39: 83 | Q39: =1612+1251 -> 2863 | R39: =2590 -> 2590 | V39: 44308 | W39: =DAYS(TODAY(),V39) -> 1864
O41: =SUM(I29:I39)/E3 -> 0

Sheet Futrures Holdings
A2: Asset Type | B2: Underlying | C2: Futures Symbol | D2: Market | E2: Direction | F2: Contracts | G2: Multiplier | H2: Entry Price | I2: Current Price | J2: Notional Exposure | K2: Margin Used | L2: Unrealized P/L | M2: Realized P/L | N2: Net Exposure | O2: Expiry | P2: Strategy Tag | Q2: Currency | R2: FX Rate | S2: Notional Exposure (TWD) | T2: Margin Used (TWD) | U2: Unrealized P/L (TWD) | V2: Notes

Sheet Holding Funds

Sheet Option Tracker
A1: Type | B1: Open | C1: Expire | D1: Close | E1: Ticker | F1: Event | G1: Strike | H1: IV | I1: Qty | J1: Fill$ | K1: Close$ | L1: P/L | M1: Days | N1: ROI | O1: AROI | P1: Notes
A2: Sell | B2: 45789 | C2: 45807 | D2: 45807 | E2: NVO | F2: Put Spread | G2: 62/61 | H2: ? | I2: 1 | J2: 0.25 | K2: 0 | L2: =(J2-K2)*100*I2 -> 25 | M2: =D2-B2 -> 18 | N2: =L2/(100-L2) -> 0.33333333 | O2: =(1+N2)^(1/(M2/365))-1 -> 340.57017
A3: Sell | B3: 45804 | C3: 45806 | D3: 45806 | E3: SPY | F3: Put Spread | G3: 578/577 | H3: ? | I3: 1 | J3: 0.14 | K3: 0 | L3: =(J3-K3)*100*I3 -> 14 | M3: =D3-B3 -> 2 | N3: =L3/(100-L3) -> 0.1627907 | O3: =(1+N3)^(1/(M3/365))-1 -> 899565203721
A4: Sell | B4: 45807 | C4: 45811 | D4: 45811 | E4: SPY | F4: Put Spread | G4: 580/579 | H4: ? | I4: 1 | J4: 0.15 | K4: 0 | L4: =(J4-K4)*100*I4 -> 15 | M4: =D4-B4 -> 4 | N4: =L4/(100-L4) -> 0.17647059 | O4: =(1+N4)^(1/(M4/365))-1 -> 2757546.7
A5: Sell | B5: 45811 | C5: 45828 | D5: 45825 | E5: PEP | F5: IC | G5: 135/136|125/124 | H5: 0.248 | I5: 1 | J5: 0.33 | K5: 0.1 | L5: =(J5-K5)*100*I5 -> 23 | M5: =D5-B5 -> 14 | N5: =L5/(100-L5) -> 0.2987013 | O5: =(1+N5)^(1/(M5/365))-1 -> 909.64467 | P5: https://www.reddit.com/r/thetagang/s/r3P8jUIPaV
